Traceback (most recent call last):
  File "queue_process.py", line 27, in queue_client
    current_turn = await socket.recv()
  File "/usr/local/lib/python3.6/dist-packages/websockets/protocol.py", line 484, in recv
    await self.ensure_open()
  File "/usr/local/lib/python3.6/dist-packages/websockets/protocol.py", line 780, in ensure_open
    raise self.connection_closed_exc()
websockets.exceptions.ConnectionClosedOK: code = 1000 (OK), no reason
Traceback (most recent call last):
  File "queue_process.py", line 27, in queue_client
    current_turn = await socket.recv()
  File "/usr/local/lib/python3.6/dist-packages/websockets/protocol.py", line 484, in recv
    await self.ensure_open()
  File "/usr/local/lib/python3.6/dist-packages/websockets/protocol.py", line 780, in ensure_open
    raise self.connection_closed_exc()
websockets.exceptions.ConnectionClosedOK: code = 1000 (OK), no reason
Traceback (most recent call last):
  File "queue_process.py", line 27, in queue_client
    current_turn = await socket.recv()
  File "/usr/local/lib/python3.6/dist-packages/websockets/protocol.py", line 484, in recv
    await self.ensure_open()
  File "/usr/local/lib/python3.6/dist-packages/websockets/protocol.py", line 780, in ensure_open
    raise self.connection_closed_exc()
websockets.exceptions.ConnectionClosedOK: code = 1000 (OK), no reason
Traceback (most recent call last):
  File "queue_process.py", line 27, in queue_client
    current_turn = await socket.recv()
  File "/usr/local/lib/python3.6/dist-packages/websockets/protocol.py", line 484, in recv
    await self.ensure_open()
  File "/usr/local/lib/python3.6/dist-packages/websockets/protocol.py", line 780, in ensure_open
    raise self.connection_closed_exc()
websockets.exceptions.ConnectionClosedOK: code = 1000 (OK), no reason
Traceback (most recent call last):
  File "queue_process.py", line 21, in queue_client
    async with websockets.connect("ws://"+server_ip+":"+str(QUEUE_PORT)) as socket:
  File "/usr/local/lib/python3.6/dist-packages/websockets/client.py", line 519, in __aenter__
    return await self
  File "/usr/local/lib/python3.6/dist-packages/websockets/client.py", line 537, in __await_impl__
    transport, protocol = await self._create_connection()
  File "/usr/lib/python3.6/asyncio/base_events.py", line 794, in create_connection
    raise exceptions[0]
  File "/usr/lib/python3.6/asyncio/base_events.py", line 781, in create_connection
    yield from self.sock_connect(sock, address)
  File "/usr/lib/python3.6/asyncio/selector_events.py", line 439, in sock_connect
    return (yield from fut)
  File "/usr/lib/python3.6/asyncio/selector_events.py", line 469, in _sock_connect_cb
    raise OSError(err, 'Connect call failed %s' % (address,))
ConnectionRefusedError: [Errno 111] Connect call failed ('202.92.132.191', 10015)
